Workbook

Sheet Resumen
A1: De multifondos a fondos generacionales: riesgo, regímenes y pensiones en Chile
A2: Datos: 01-01-2002 a 16-09-2026. Valores en azul provienen del pipeline en Python (run_pipeline.py).
A4: # | B4: Hallazgo | C4: Evidencia
A5: 1 | B5: La inflación se lleva ~3,9 puntos al año: la rentabilidad real es mucho menor que la publicitada. | C5: Fondo A: 9,9% nominal vs 5,8% real; Fondo E: 6,8% vs 2,8% (ago-2002 a ago-2026).
A6: 2 | B6: El Fondo E no es un refugio: su peor caída real fue mayor que la del D y similar a la del C. | C6: Máx. caída real: C -24,4%, D -21,9%, E -24,3%.
A7: 3 | B7: Desde 2019 el mercado chileno opera en un régimen nuevo, nunca visto antes. | C7: El HMM (3 estados, BIC) detecta un régimen que domina desde 05-2019; en él el Fondo E tiene volatilidad real de 8,9% (vs 2,4% en calma) y la correlación C–E subió a 0,81 (IC 90%: 0,69 a 0,89). Bootstrap paramétrico (200 réplicas): volatilidad del E en ese régimen entre 5,9% y 10,2%; el régimen se recupera (>50% de los meses desde el quiebre) en 92% de las réplicas.
A8: 4 | B8: Con la trayectoria oficial de los fondos generacionales, el ciclo de vida supera al fondo por defecto actual. | C8: Hombre: mediana 14,8 vs 10,1 UF (+46%); percentil 5: 7,2 vs 6,0 UF. Sin extrapolar sobre el Fondo A: +40%. Con historias alternativas (bootstrap por bloques) el IC 90% es -14% a +120%: ver hallazgo 9.
A9: 5 | B9: Cambiarse de fondo reaccionando a las caídas no mejora la pensión esperada y suele costar. | C9: Mediana -4,9% y percentil 5 -8,3% vs el por defecto (≈15 traspasos). En la historia 2002-2026 la misma regla quedó en +2,3%: un solo camino no basta para juzgar. Con historias alternativas el IC 90% es -8,7% a +8,5%.
A10: 6 | B10: La brecha de género es estructural, incluso con el mismo sueldo y la misma estrategia. | C10: Por defecto: hombre 10,1 UF vs mujer 6,5 UF (-36%): 5 años menos de ahorro y mayor longevidad (CNU 234 vs 194).
A11: 7 | B11: Las bandas de premios y castigos son ~3 veces más anchas que la dispersión histórica entre AFP. | C11: El 95% de las desviaciones de 36 meses vs pares es menor a 0,83%; con banda ±2,4% solo 0,2% de los AFP-meses habría quedado fuera, y con la banda de transición de ±4,0% (abr-2028 a mar-2031), 0,0%. El incentivo dependerá de cuánto difiera la cartera de referencia de lo que hoy invierten las AFP.
A12: 8 | B12: Las dos conclusiones sobre estrategias resisten 13 supuestos alternativos, y reaccionar más rápido cuesta más. | C12: El ciclo de vida supera al por defecto en 91%–93% de los escenarios en todos los casos (mediana +28% a +51%). La regla reactiva pierde en la mediana en los 13 casos: -9,7% si reacciona ante caídas de 4% (≈26 traspasos) y -0,9% si espera caídas de 10%.
A13: 9 | B13: La ventaja del ciclo de vida es, en el fondo, una apuesta a la prima de la renta variable, y 24 años de historia no la aseguran. | C13: Remuestreando la historia por bloques (200 historias), la prima real del A sobre el E va de -2,0% a +7,2% (IC 90%) y explica la ventaja del ciclo de vida (correlación 0,94). El ciclo de vida gana en la mediana en 86% de las historias; cuando la prima es negativa, pierde.
A14: 10 | B14: Con las expectativas de mercado actuales, la ventaja del ciclo de vida es real pero mucho menor que la histórica. | C14: Recentrando los escenarios en el consenso 2026 (renta fija UF 2,52%, renta variable global 4,4% real): Fondo A 4,1% y E 2,7% real/año; ciclo de vida vs por defecto +12% en la mediana (vs +46% con la historia), percentil 5 -2%, gana en 68% de los escenarios. Sin prima de crecimiento: -1%. La probabilidad de alcanzar una tasa de reemplazo de 40% es 10% (por defecto) y 25% (ciclo de vida).
A15: 11 | B15: La reforma de 2025 cambia más la pensión que cualquier estrategia de inversión: la tasa de reemplazo se duplica. | C15: Fondo por defecto, consenso 2026. Hombre: solo con el 10% del trabajador, tasa de reemplazo mediana 27% (10% llega a 40%); con cotización del empleador, rentabilidad protegida y PGU, 58% (98% llega a 40%). Mujer (PGU desde los 65): 17% → 43%. La PGU es progresiva: con sueldo de 15 UF la tasa total es 69% y con 60 UF, 40%.
A16: 12 | B16: El glidepath oficial está muy cerca del óptimo, y la PGU justifica llegar al retiro con más riesgo. | C16: Maximizando la utilidad CRRA de la pensión total (hombre, consenso 2026, escenarios de prueba), el mejor glidepath de la familia supera al oficial en solo +0,3% a +3,1% de pensión equivalente cierta (aversión γ de 2 a 5); el fondo por defecto de la ley queda -9% a -1% bajo el oficial. Con γ = 3, el óptimo llega al retiro con 70% en crecimiento si se cuenta la PGU y 40% sin ella (el oficial, 29%): la PGU actúa como un bono.
... A20: 16 | B20: Los regímenes mejoran la predicción del mes siguiente, pero las variables macro no ayudan a anticiparlos. | C20: Validación fuera de muestra 2015-2026 (140 meses, reestimación anual): el HMM supera a una normal sin regímenes en +0,74 de log-score por mes (Diebold-Mariano p = 0,001). Agregar IPC, TPM, dólar e Imacec a las transiciones (TVTP) no mejora: -0,001 por mes (p = 0,98). Dentro de muestra, una TPM que sube 1 desviación estándar eleva la probabilidad de pasar de la calma a la crisis de 4% a 16%, pero el quiebre de 2019 ocurrió una sola vez: no hay transiciones suficientes para aprender qué lo gatilla.

Sheet Simulador_Pension
A1: Simulador de pensión por Retiro Programado (primer año)
A2: Cambia los valores amarillos en 'Parametros'. Simplificación: sin beneficiarios de sobrevivencia.
B4: Sexo | C4: =Parametros!B2
B5: Edad al pensionarse | C5: =Parametros!B3
B6: Saldo (UF) | C6: =Parametros!B4
B7: TITRP | C7: =Parametros!B6
B8: Capital Necesario Unitario (CNU) | C8: =SUM(H12:H731)
B9: Pensión mensual (UF) | C9: =C6/C8
B10: Pensión mensual (CLP) | C10: =C9*Parametros!B7
A11: Mes k | B11: Edad | C11: Año | D11: qx anual | E11: q mensual | F11: Prob. vivo al pago | G11: Factor descuento | H11: VP pago
A12: 0 | B12: =$C$5+INT(A12/12) | C12: =Parametros!$B$5+INT(A12/12) | D12: =IFERROR(IF($C$4="H",INDEX(Mortalidad_H!$B$3:$BX$113,MATCH(B12,Mortalidad_H!$A$3:$A$113,0),MATCH(MIN(C12,2100),Mortalidad_H!$B$2:$BX$2,0)),INDEX(Mortalidad_M!$B$3:$BX$93,MATCH(B12,Mortalidad_M!$A$3:$A$93,0),MATCH(MIN(C12,2100),Mortalidad_M!$B$2:$BX$2,0))),1) | E12: =1-(1-D12)^(1/12) | F12: 1 | G12: =1/(1+$C$7)^(A12/12) | H12: =F12*G12
A13: 1 | B13: =$C$5+INT(A13/12) | C13: =Parametros!$B$5+INT(A13/12) | D13: =IFERROR(IF($C$4="H",INDEX(Mortalidad_H!$B$3:$BX$113,MATCH(B13,Mortalidad_H!$A$3:$A$113,0),MATCH(MIN(C13,2100),Mortalidad_H!$B$2:$BX$2,0)),INDEX(Mortalidad_M!$B$3:$BX$93,MATCH(B13,Mortalidad_M!$A$3:$A$93,0),MATCH(MIN(C13,2100),Mortalidad_M!$B$2:$BX$2,0))),1) | E13: =1-(1-D13)^(1/12) | F13: =F12*(1-E12) | G13: =1/(1+$C$7)^(A13/12) | H13: =F13*G13
A14: 2 | B14: =$C$5+INT(A14/12) | C14: =Parametros!$B$5+INT(A14/12) | D14: =IFERROR(IF($C$4="H",INDEX(Mortalidad_H!$B$3:$BX$113,MATCH(B14,Mortalidad_H!$A$3:$A$113,0),MATCH(MIN(C14,2100),Mortalidad_H!$B$2:$BX$2,0)),INDEX(Mortalidad_M!$B$3:$BX$93,MATCH(B14,Mortalidad_M!$A$3:$A$93,0),MATCH(MIN(C14,2100),Mortalidad_M!$B$2:$BX$2,0))),1) | E14: =1-(1-D14)^(1/12) | F14: =F13*(1-E13) | G14: =1/(1+$C$7)^(A14/12) | H14: =F14*G14
A15: 3 | B15: =$C$5+INT(A15/12) | C15: =Parametros!$B$5+INT(A15/12) | D15: =IFERROR(IF($C$4="H",INDEX(Mortalidad_H!$B$3:$BX$113,MATCH(B15,Mortalidad_H!$A$3:$A$113,0),MATCH(MIN(C15,2100),Mortalidad_H!$B$2:$BX$2,0)),INDEX(Mortalidad_M!$B$3:$BX$93,MATCH(B15,Mortalidad_M!$A$3:$A$93,0),MATCH(MIN(C15,2100),Mortalidad_M!$B$2:$BX$2,0))),1) | E15: =1-(1-D15)^(1/12) | F15: =F14*(1-E14) | G15: =1/(1+$C$7)^(A15/12) | H15: =F15*G15
A16: 4 | B16: =$C$5+INT(A16/12) | C16: =Parametros!$B$5+INT(A16/12) | D16: =IFERROR(IF($C$4="H",INDEX(Mortalidad_H!$B$3:$BX$113,MATCH(B16,Mortalidad_H!$A$3:$A$113,0),MATCH(MIN(C16,2100),Mortalidad_H!$B$2:$BX$2,0)),INDEX(Mortalidad_M!$B$3:$BX$93,MATCH(B16,Mortalidad_M!$A$3:$A$93,0),MATCH(MIN(C16,2100),Mortalidad_M!$B$2:$BX$2,0))),1) | E16: =1-(1-D16)^(1/12) | F16: =F15*(1-E15) | G16: =1/(1+$C$7)^(A16/12) | H16: =F16*G16
A17: 5 | B17: =$C$5+INT(A17/12) | C17: =Parametros!$B$5+INT(A17/12) | D17: =IFERROR(IF($C$4="H",INDEX(Mortalidad_H!$B$3:$BX$113,MATCH(B17,Mortalidad_H!$A$3:$A$113,0),MATCH(MIN(C17,2100),Mortalidad_H!$B$2:$BX$2,0)),INDEX(Mortalidad_M!$B$3:$BX$93,MATCH(B17,Mortalidad_M!$A$3:$A$93,0),MATCH(MIN(C17,2100),Mortalidad_M!$B$2:$BX$2,0))),1) | E17: =1-(1-D17)^(1/12) | F17: =F16*(1-E16) | G17: =1/(1+$C$7)^(A17/12) | H17: =F17*G17
A18: 6 | B18: =$C$5+INT(A18/12) | C18: =Parametros!$B$5+INT(A18/12) | D18: =IFERROR(IF($C$4="H",INDEX(Mortalidad_H!$B$3:$BX$113,MATCH(B18,Mortalidad_H!$A$3:$A$113,0),MATCH(MIN(C18,2100),Mortalidad_H!$B$2:$BX$2,0)),INDEX(Mortalidad_M!$B$3:$BX$93,MATCH(B18,Mortalidad_M!$A$3:$A$93,0),MATCH(MIN(C18,2100),Mortalidad_M!$B$2:$BX$2,0))),1) | E18: =1-(1-D18)^(1/12) | F18: =F17*(1-E17) | G18: =1/(1+$C$7)^(A18/12) | H18: =F18*G18
A19: 7 | B19: =$C$5+INT(A19/12) | C19: =Parametros!$B$5+INT(A19/12) | D19: =IFERROR(IF($C$4="H",INDEX(Mortalidad_H!$B$3:$BX$113,MATCH(B19,Mortalidad_H!$A$3:$A$113,0),MATCH(MIN(C19,2100),Mortalidad_H!$B$2:$BX$2,0)),INDEX(Mortalidad_M!$B$3:$BX$93,MATCH(B19,Mortalidad_M!$A$3:$A$93,0),MATCH(MIN(C19,2100),Mortalidad_M!$B$2:$BX$2,0))),1) | E19: =1-(1-D19)^(1/12) | F19: =F18*(1-E18) | G19: =1/(1+$C$7)^(A19/12) | H19: =F19*G19
A20: 8 | B20: =$C$5+INT(A20/12) | C20: =Parametros!$B$5+INT(A20/12) | D20: =IFERROR(IF($C$4="H",INDEX(Mortalidad_H!$B$3:$BX$113,MATCH(B20,Mortalidad_H!$A$3:$A$113,0),MATCH(MIN(C20,2100),Mortalidad_H!$B$2:$BX$2,0)),INDEX(Mortalidad_M!$B$3:$BX$93,MATCH(B20,Mortalidad_M!$A$3:$A$93,0),MATCH(MIN(C20,2100),Mortalidad_M!$B$2:$BX$2,0))),1) | E20: =1-(1-D20)^(1/12) | F20: =F19*(1-E19) | G20: =1/(1+$C$7)^(A20/12) | H20: =F20*G20
A21: 9 | B21: =$C$5+INT(A21/12) | C21: =Parametros!$B$5+INT(A21/12) | D21: =IFERROR(IF($C$4="H",INDEX(Mortalidad_H!$B$3:$BX$113,MATCH(B21,Mortalidad_H!$A$3:$A$113,0),MATCH(MIN(C21,2100),Mortalidad_H!$B$2:$BX$2,0)),INDEX(Mortalidad_M!$B$3:$BX$93,MATCH(B21,Mortalidad_M!$A$3:$A$93,0),MATCH(MIN(C21,2100),Mortalidad_M!$B$2:$BX$2,0))),1) | E21: =1-(1-D21)^(1/12) | F21: =F20*(1-E20) | G21: =1/(1+$C$7)^(A21/12) | H21: =F21*G21
A22: 10 | B22: =$C$5+INT(A22/12) | C22: =Parametros!$B$5+INT(A22/12) | D22: =IFERROR(IF($C$4="H",INDEX(Mortalidad_H!$B$3:$BX$113,MATCH(B22,Mortalidad_H!$A$3:$A$113,0),MATCH(MIN(C22,2100),Mortalidad_H!$B$2:$BX$2,0)),INDEX(Mortalidad_M!$B$3:$BX$93,MATCH(B22,Mortalidad_M!$A$3:$A$93,0),MATCH(MIN(C22,2100),Mortalidad_M!$B$2:$BX$2,0))),1) | E22: =1-(1-D22)^(1/12) | F22: =F21*(1-E21) | G22: =1/(1+$C$7)^(A22/12) | H22: =F22*G22
A23: 11 | B23: =$C$5+INT(A23/12) | C23: =Parametros!$B$5+INT(A23/12) | D23: =IFERROR(IF($C$4="H",INDEX(Mortalidad_H!$B$3:$BX$113,MATCH(B23,Mortalidad_H!$A$3:$A$113,0),MATCH(MIN(C23,2100),Mortalidad_H!$B$2:$BX$2,0)),INDEX(Mortalidad_M!$B$3:$BX$93,MATCH(B23,Mortalidad_M!$A$3:$A$93,0),MATCH(MIN(C23,2100),Mortalidad_M!$B$2:$BX$2,0))),1) | E23: =1-(1-D23)^(1/12) | F23: =F22*(1-E22) | G23: =1/(1+$C$7)^(A23/12) | H23: =F23*G23
A24: 12 | B24: =$C$5+INT(A24/12) | C24: =Parametros!$B$5+INT(A24/12) | D24: =IFERROR(IF($C$4="H",INDEX(Mortalidad_H!$B$3:$BX$113,MATCH(B24,Mortalidad_H!$A$3:$A$113,0),MATCH(MIN(C24,2100),Mortalidad_H!$B$2:$BX$2,0)),INDEX(Mortalidad_M!$B$3:$BX$93,MATCH(B24,Mortalidad_M!$A$3:$A$93,0),MATCH(MIN(C24,2100),Mortalidad_M!$B$2:$BX$2,0))),1) | E24: =1-(1-D24)^(1/12) | F24: =F23*(1-E23) | G24: =1/(1+$C$7)^(A24/12) | H24: =F24*G24
... A731: 719 | B731: =$C$5+INT(A731/12) | C731: =Parametros!$B$5+INT(A731/12) | D731: =IFERROR(IF($C$4="H",INDEX(Mortalidad_H!$B$3:$BX$113,MATCH(B731,Mortalidad_H!$A$3:$A$113,0),MATCH(MIN(C731,2100),Mortalidad_H!$B$2:$BX$2,0)),INDEX(Mortalidad_M!$B$3:$BX$93,MATCH(B731,Mortalidad_M!$A$3:$A$93,0),MATCH(MIN(C731,2100),Mortalidad_M!$B$2:$BX$2,0))),1) | E731: =1-(1-D731)^(1/12) | F731: =F730*(1-E730) | G731: =1/(1+$C$7)^(A731/12) | H731: =F731*G731

Sheet Parametros
A1: Parámetro | B1: Valor | C1: Descripción / fuente
A2: Sexo (H/M) | B2: H | C2: H usa CB-H-2020; M usa RV-M-2020 (CMF/SP, NCG 495, 2023)
A3: Edad al pensionarse | B3: 65 | C3: Edad legal: 65 hombres, 60 mujeres
A4: Saldo acumulado (UF) | B4: 3000 | C4: Saldo de la cuenta individual al pensionarse
A5: Año de cálculo | B5: 2026 | C5: Año desde el que se proyecta la mortalidad
A6: TITRP anual | B6: 0.0345 | C6: Tasa técnica de retiro programado, vigente desde 2026-07 (Circular SP N.º 2417)
A7: Valor UF (CLP) | B7: 41024.46 | C7: UF al 26-09-2026 (Banco Central)
A9: Celda amarilla con texto azul = editable. Negro = fórmula. Verde = vínculo a otra hoja.
A11: Supuestos de la simulación Monte Carlo (config.py)
A12: n_simulaciones | B12: 10000
A13: semilla | B13: 20260927
A14: edad_inicio | B14: 25
A15: anio_inicio | B15: 2026
A16: sueldo_inicial_uf | B16: 25
A17: crecimiento_real_sueldo | B17: 0.015
A18: edad_fin_crecimiento | B18: 50
A19: tasa_cotizacion | B19: 0.1
A20: densidad_cotizacion | B20: 0.6
A21: ajuste_retorno_anual | B21: 0
A22: tasa_reemplazo_meta | B22: 0.4

Sheet Mortalidad_H
A1: qx proyectado = qx_2020 × Π(1 − AA x,t), tabla CB-H-2020. Filas: edad; columnas: año. Desde 2036 el factor AA se mantiene constante.
A2: Edad | B2: 2026 | C2: 2027 | D2: 2028 | E2: 2029 | F2: 2030 | G2: 2031 | H2: 2032 | I2: 2033 | J2: 2034 | K2: 2035 | L2: 2036 | M2: 2037 | N2: 2038 | O2: 2039 | P2: 2040 | Q2: 2041 | R2: 2042 | S2: 2043 | T2: 2044 | U2: 2045 | V2: 2046 | W2: 2047 | X2: 2048 | Y2: 2049 | Z2: 2050 | AA2: 2051 | AB2: 2052 | AC2: 2053 | AD2: 2054 | AE2: 2055 | AF2: 2056 | AG2: 2057 | AH2: 2058 | AI2: 2059 | AJ2: 2060 | AK2: 2061 | AL2: 2062 | AM2: 2063 | AN2: 2064 | AO2: 2065 | AP2: 2066 | AQ2: 2067 | AR2: 2068 | AS2: 2069 | AT2: 2070 | AU2: 2071 | AV2: 2072 | AW2: 2073 | AX2: 2074 | AY2: 2075 | AZ2: 2076 | BA2: 2077 | BB2: 2078 | BC2: 2079 | BD2: 2080 | BE2: 2081 | BF2: 2082 | BG2: 2083 | BH2: 2084 | BI2: 2085 | BJ2: 2086 | BK2: 2087 | BL2: 2088 | BM2: 2089 | BN2: 2090 | BO2: 2091 | BP2: 2092 | BQ2: 2093 | BR2: 2094 | BS2: 2095 | BT2: 2096 | BU2: 2097 | BV2: 2098 | BW2: 2099 | BX2: 2100
A3: 0 | B3: 0.00500701 | C3: 0.00488222 | D3: 0.00477307 | E3: 0.00467813 | F3: 0.00459587 | G3: 0.0045247 | H3: 0.00446293 | I3: 0.00440878 | J3: 0.00436035 | K3: 0.00431564 | L3: 0.00427248 | M3: 0.00422976 | N3: 0.00418746 | O3: 0.00414559 | P3: 0.00410413 | Q3: 0.00406309 | R3: 0.00402246 | S3: 0.00398223 | T3: 0.00394241 | U3: 0.00390299 | V3: 0.00386396 | W3: 0.00382532 | X3: 0.00378706 | Y3: 0.00374919 | Z3: 0.0037117 | AA3: 0.00367458 | AB3: 0.00363784 | AC3: 0.00360146 | AD3: 0.00356545 | AE3: 0.00352979 | AF3: 0.00349449 | AG3: 0.00345955 | AH3: 0.00342495 | AI3: 0.0033907 | AJ3: 0.0033568 | AK3: 0.00332323 | AL3: 0.00329 | AM3: 0.0032571 | AN3: 0.00322452 | AO3: 0.00319228 | AP3: 0.00316036 | AQ3: 0.00312875 | AR3: 0.00309747 | AS3: 0.00306649 | AT3: 0.00303583 | AU3: 0.00300547 | AV3: 0.00297541 | AW3: 0.00294566 | AX3: 0.0029162 | AY3: 0.00288704 | AZ3: 0.00285817 | BA3: 0.00282959 | BB3: 0.00280129 | BC3: 0.00277328 | BD3: 0.00274555 | BE3: 0.00271809 | BF3: 0.00269091 | BG3: 0.002664 | BH3: 0.00263736 | BI3: 0.00261099 | BJ3: 0.00258488 | BK3: 0.00255903 | BL3: 0.00253344 | BM3: 0.0025081 | BN3: 0.00248302 | BO3: 0.00245819 | BP3: 0.00243361 | BQ3: 0.00240928 | BR3: 0.00238518 | BS3: 0.00236133 | BT3: 0.00233772 | BU3: 0.00231434 | BV3: 0.0022912 | BW3: 0.00226828 | BX3: 0.0022456
A4: 1 | B4: 0.00026952 | C4: 0.00026286 | D4: 0.00025702 | E4: 0.00025194 | F4: 0.00024754 | G4: 0.00024372 | H4: 0.00024041 | I4: 0.0002375 | J4: 0.00023489 | K4: 0.00023249 | L4: 0.00023016 | M4: 0.00022786 | N4: 0.00022558 | O4: 0.00022333 | P4: 0.00022109 | Q4: 0.00021888 | R4: 0.00021669 | S4: 0.00021453 | T4: 0.00021238 | U4: 0.00021026 | V4: 0.00020815 | W4: 0.00020607 | X4: 0.00020401 | Y4: 0.00020197 | Z4: 0.00019995 | AA4: 0.00019795 | AB4: 0.00019597 | AC4: 0.00019401 | AD4: 0.00019207 | AE4: 0.00019015 | AF4: 0.00018825 | AG4: 0.00018637 | AH4: 0.0001845 | AI4: 0.00018266 | AJ4: 0.00018083 | AK4: 0.00017902 | AL4: 0.00017723 | AM4: 0.00017546 | AN4: 0.00017371 | AO4: 0.00017197 | AP4: 0.00017025 | AQ4: 0.00016855 | AR4: 0.00016686 | AS4: 0.00016519 | AT4: 0.00016354 | AU4: 0.00016191 | AV4: 0.00016029 | AW4: 0.00015868 | AX4: 0.0001571 | AY4: 0.00015553 | AZ4: 0.00015397 | BA4: 0.00015243 | BB4: 0.00015091 | BC4: 0.0001494 | BD4: 0.0001479 | BE4: 0.00014643 | BF4: 0.00014496 | BG4: 0.00014351 | BH4: 0.00014208 | BI4: 0.00014066 | BJ4: 0.00013925 | BK4: 0.00013786 | BL4: 0.00013648 | BM4: 0.00013511 | BN4: 0.00013376 | BO4: 0.00013242 | BP4: 0.0001311 | BQ4: 0.00012979 | BR4: 0.00012849 | BS4: 0.00012721 | BT4: 0.00012593 | BU4: 0.00012467 | BV4: 0.00012343 | BW4: 0.00012219 | BX4: 0.00012097
A5: 2 | B5: 0.0001637 | C5: 0.0001597 | D5: 0.00015619 | E5: 0.00015313 | F5: 0.00015047 | G5: 0.00014817 | H5: 0.00014616 | I5: 0.0001444 | J5: 0.00014282 | K5: 0.00014135 | L5: 0.00013994 | M5: 0.00013854 | N5: 0.00013715 | O5: 0.00013578 | P5: 0.00013442 | Q5: 0.00013308 | R5: 0.00013175 | S5: 0.00013043 | T5: 0.00012913 | U5: 0.00012784 | V5: 0.00012656 | W5: 0.00012529 | X5: 0.00012404 | Y5: 0.0001228 | Z5: 0.00012157 | AA5: 0.00012036 | AB5: 0.00011915 | AC5: 0.00011796 | AD5: 0.00011678 | AE5: 0.00011561 | AF5: 0.00011446 | AG5: 0.00011331 | AH5: 0.00011218 | AI5: 0.00011106 | AJ5: 0.00010995 | AK5: 0.00010885 | AL5: 0.00010776 | AM5: 0.00010668 | AN5: 0.00010561 | AO5: 0.00010456 | AP5: 0.00010351 | AQ5: 0.00010248 | AR5: 0.00010145 | AS5: 0.00010044 | AT5: 9.943e-05 | AU5: 9.844e-05 | AV5: 9.746e-05 | AW5: 9.648e-05 | AX5: 9.552e-05 | AY5: 9.456e-05 | AZ5: 9.362e-05 | BA5: 9.268e-05 | BB5: 9.175e-05 | BC5: 9.083e-05 | BD5: 8.993e-05 | BE5: 8.903e-05 | BF5: 8.814e-05 | BG5: 8.726e-05 | BH5: 8.638e-05 | BI5: 8.552e-05 | BJ5: 8.466e-05 | BK5: 8.382e-05 | BL5: 8.298e-05 | BM5: 8.215e-05 | BN5: 8.133e-05 | BO5: 8.051e-05 | BP5: 7.971e-05 | BQ5: 7.891e-05 | BR5: 7.812e-05 | BS5: 7.734e-05 | BT5: 7.657e-05 | BU5: 7.58e-05 | BV5: 7.504e-05 | BW5: 7.429e-05 | BX5: 7.355e-05
A6: 3 | B6: 0.00013387 | C6: 0.00013064 | D6: 0.00012781 | E6: 0.00012534 | F6: 0.00012318 | G6: 0.00012131 | H6: 0.00011968 | I6: 0.00011824 | J6: 0.00011695 | K6: 0.00011575 | L6: 0.00011459 | M6: 0.00011345 | N6: 0.00011231 | O6: 0.00011119 | P6: 0.00011008 | Q6: 0.00010898 | R6: 0.00010789 | S6: 0.00010681 | T6: 0.00010574 | U6: 0.00010468 | V6: 0.00010364 | W6: 0.0001026 | X6: 0.00010157 | Y6: 0.00010056 | Z6: 9.955e-05 | AA6: 9.856e-05 | AB6: 9.757e-05 | AC6: 9.659e-05 | AD6: 9.563e-05 | AE6: 9.467e-05 | AF6: 9.373e-05 | AG6: 9.279e-05 | AH6: 9.186e-05 | AI6: 9.094e-05 | AJ6: 9.003e-05 | AK6: 8.913e-05 | AL6: 8.824e-05 | AM6: 8.736e-05 | AN6: 8.648e-05 | AO6: 8.562e-05 | AP6: 8.476e-05 | AQ6: 8.392e-05 | AR6: 8.308e-05 | AS6: 8.225e-05 | AT6: 8.142e-05 | AU6: 8.061e-05 | AV6: 7.98e-05 | AW6: 7.901e-05 | AX6: 7.822e-05 | AY6: 7.743e-05 | AZ6: 7.666e-05 | BA6: 7.589e-05 | BB6: 7.513e-05 | BC6: 7.438e-05 | BD6: 7.364e-05 | BE6: 7.29e-05 | BF6: 7.217e-05 | BG6: 7.145e-05 | BH6: 7.074e-05 | BI6: 7.003e-05 | BJ6: 6.933e-05 | BK6: 6.864e-05 | BL6: 6.795e-05 | BM6: 6.727e-05 | BN6: 6.66e-05 | BO6: 6.593e-05 | BP6: 6.527e-05 | BQ6: 6.462e-05 | BR6: 6.397e-05 | BS6: 6.333e-05 | BT6: 6.27e-05 | BU6: 6.207e-05 | BV6: 6.145e-05 | BW6: 6.084e-05 | BX6: 6.023e-05
A7: 4 | B7: 0.00011411 | C7: 0.0001114 | D7: 0.00010902 | E7: 0.00010694 | F7: 0.00010513 | G7: 0.00010355 | H7: 0.00010216 | I7: 0.00010094 | J7: 9.984e-05 | K7: 9.882e-05 | L7: 9.783e-05 | M7: 9.685e-05 | N7: 9.588e-05 | O7: 9.493e-05 | P7: 9.398e-05 | Q7: 9.304e-05 | R7: 9.211e-05 | S7: 9.119e-05 | T7: 9.027e-05 | U7: 8.937e-05 | V7: 8.848e-05 | W7: 8.759e-05 | X7: 8.672e-05 | Y7: 8.585e-05 | Z7: 8.499e-05 | AA7: 8.414e-05 | AB7: 8.33e-05 | AC7: 8.247e-05 | AD7: 8.164e-05 | AE7: 8.083e-05 | AF7: 8.002e-05 | AG7: 7.922e-05 | AH7: 7.842e-05 | AI7: 7.764e-05 | AJ7: 7.686e-05 | AK7: 7.61e-05 | AL7: 7.533e-05 | AM7: 7.458e-05 | AN7: 7.384e-05 | AO7: 7.31e-05 | AP7: 7.237e-05 | AQ7: 7.164e-05 | AR7: 7.093e-05 | AS7: 7.022e-05 | AT7: 6.951e-05 | AU7: 6.882e-05 | AV7: 6.813e-05 | AW7: 6.745e-05 | AX7: 6.678e-05 | AY7: 6.611e-05 | AZ7: 6.545e-05 | BA7: 6.479e-05 | BB7: 6.414e-05 | BC7: 6.35e-05 | BD7: 6.287e-05 | BE7: 6.224e-05 | BF7: 6.162e-05 | BG7: 6.1e-05 | BH7: 6.039e-05 | BI7: 5.979e-05 | BJ7: 5.919e-05 | BK7: 5.86e-05 | BL7: 5.801e-05 | BM7: 5.743e-05 | BN7: 5.686e-05 | BO7: 5.629e-05 | BP7: 5.572e-05 | BQ7: 5.517e-05 | BR7: 5.462e-05 | BS7: 5.407e-05 | BT7: 5.353e-05 | BU7: 5.299e-05 | BV7: 5.246e-05 | BW7: 5.194e-05 | BX7: 5.142e-05
A8: 5 | B8: 0.00010518 | C8: 0.00010273 | D8: 0.00010058 | E8: 9.869e-05 | F8: 9.704e-05 | G8: 9.56e-05 | H8: 9.433e-05 | I8: 9.321e-05 | J8: 9.22e-05 | K8: 9.126e-05 | L8: 9.034e-05 | M8: 8.944e-05 | N8: 8.855e-05 | O8: 8.766e-05 | P8: 8.678e-05 | Q8: 8.592e-05 | R8: 8.506e-05 | S8: 8.421e-05 | T8: 8.336e-05 | U8: 8.253e-05 | V8: 8.171e-05 | W8: 8.089e-05 | X8: 8.008e-05 | Y8: 7.928e-05 | Z8: 7.849e-05 | AA8: 7.77e-05 | AB8: 7.692e-05 | AC8: 7.615e-05 | AD8: 7.539e-05 | AE8: 7.464e-05 | AF8: 7.389e-05 | AG8: 7.315e-05 | AH8: 7.242e-05 | AI8: 7.17e-05 | AJ8: 7.098e-05 | AK8: 7.027e-05 | AL8: 6.957e-05 | AM8: 6.887e-05 | AN8: 6.818e-05 | AO8: 6.75e-05 | AP8: 6.683e-05 | AQ8: 6.616e-05 | AR8: 6.55e-05 | AS8: 6.484e-05 | AT8: 6.419e-05 | AU8: 6.355e-05 | AV8: 6.292e-05 | AW8: 6.229e-05 | AX8: 6.166e-05 | AY8: 6.105e-05 | AZ8: 6.044e-05 | BA8: 5.983e-05 | BB8: 5.923e-05 | BC8: 5.864e-05 | BD8: 5.806e-05 | BE8: 5.748e-05 | BF8: 5.69e-05 | BG8: 5.633e-05 | BH8: 5.577e-05 | BI8: 5.521e-05 | BJ8: 5.466e-05 | BK8: 5.411e-05 | BL8: 5.357e-05 | BM8: 5.304e-05 | BN8: 5.25e-05 | BO8: 5.198e-05 | BP8: 5.146e-05 | BQ8: 5.095e-05 | BR8: 5.044e-05 | BS8: 4.993e-05 | BT8: 4.943e-05 | BU8: 4.894e-05 | BV8: 4.845e-05 | BW8: 4.796e-05 | BX8: 4.748e-05
A9: 6 | B9: 9.844e-05 | C9: 9.621e-05 | D9: 9.423e-05 | E9: 9.25e-05 | F9: 9.098e-05 | G9: 8.964e-05 | H9: 8.847e-05 | I9: 8.742e-05 | J9: 8.648e-05 | K9: 8.559e-05 | L9: 8.474e-05 | M9: 8.389e-05 | N9: 8.305e-05 | O9: 8.222e-05 | P9: 8.14e-05 | Q9: 8.058e-05 | R9: 7.978e-05 | S9: 7.898e-05 | T9: 7.819e-05 | U9: 7.741e-05 | V9: 7.663e-05 | W9: 7.587e-05 | X9: 7.511e-05 | Y9: 7.436e-05 | Z9: 7.361e-05 | AA9: 7.288e-05 | AB9: 7.215e-05 | AC9: 7.143e-05 | AD9: 7.071e-05 | AE9: 7.001e-05 | AF9: 6.931e-05 | AG9: 6.861e-05 | AH9: 6.793e-05 | AI9: 6.725e-05 | AJ9: 6.658e-05 | AK9: 6.591e-05 | AL9: 6.525e-05 | AM9: 6.46e-05 | AN9: 6.395e-05 | AO9: 6.331e-05 | AP9: 6.268e-05 | AQ9: 6.205e-05 | AR9: 6.143e-05 | AS9: 6.082e-05 | AT9: 6.021e-05 | AU9: 5.961e-05 | AV9: 5.901e-05 | AW9: 5.842e-05 | AX9: 5.784e-05 | AY9: 5.726e-05 | AZ9: 5.669e-05 | BA9: 5.612e-05 | BB9: 5.556e-05 | BC9: 5.5e-05 | BD9: 5.445e-05 | BE9: 5.391e-05 | BF9: 5.337e-05 | BG9: 5.284e-05 | BH9: 5.231e-05 | BI9: 5.178e-05 | BJ9: 5.127e-05 | BK9: 5.075e-05 | BL9: 5.025e-05 | BM9: 4.974e-05 | BN9: 4.925e-05 | BO9: 4.875e-05 | BP9: 4.827e-05 | BQ9: 4.778e-05 | BR9: 4.731e-05 | BS9: 4.683e-05 | BT9: 4.636e-05 | BU9: 4.59e-05 | BV9: 4.544e-05 | BW9: 4.499e-05 | BX9: 4.454e-05
A10: 7 | B10: 9.579e-05 | C10: 9.367e-05 | D10: 9.18e-05 | E10: 9.014e-05 | F10: 8.869e-05 | G10: 8.741e-05 | H10: 8.627e-05 | I10: 8.526e-05 | J10: 8.434e-05 | K10: 8.348e-05 | L10: 8.265e-05 | M10: 8.182e-05 | N10: 8.1e-05 | O10: 8.019e-05 | P10: 7.939e-05 | Q10: 7.859e-05 | R10: 7.781e-05 | S10: 7.703e-05 | T10: 7.626e-05 | U10: 7.55e-05 | V10: 7.474e-05 | W10: 7.4e-05 | X10: 7.326e-05 | Y10: 7.252e-05 | Z10: 7.18e-05 | AA10: 7.108e-05 | AB10: 7.037e-05 | AC10: 6.967e-05 | AD10: 6.897e-05 | AE10: 6.828e-05 | AF10: 6.76e-05 | AG10: 6.692e-05 | AH10: 6.625e-05 | AI10: 6.559e-05 | AJ10: 6.493e-05 | AK10: 6.428e-05 | AL10: 6.364e-05 | AM10: 6.3e-05 | AN10: 6.237e-05 | AO10: 6.175e-05 | AP10: 6.113e-05 | AQ10: 6.052e-05 | AR10: 5.992e-05 | AS10: 5.932e-05 | AT10: 5.872e-05 | AU10: 5.814e-05 | AV10: 5.756e-05 | AW10: 5.698e-05 | AX10: 5.641e-05 | AY10: 5.585e-05 | AZ10: 5.529e-05 | BA10: 5.473e-05 | BB10: 5.419e-05 | BC10: 5.365e-05 | BD10: 5.311e-05 | BE10: 5.258e-05 | BF10: 5.205e-05 | BG10: 5.153e-05 | BH10: 5.102e-05 | BI10: 5.051e-05 | BJ10: 5e-05 | BK10: 4.95e-05 | BL10: 4.901e-05 | BM10: 4.852e-05 | BN10: 4.803e-05 | BO10: 4.755e-05 | BP10: 4.707e-05 | BQ10: 4.66e-05 | BR10: 4.614e-05 | BS10: 4.568e-05 | BT10: 4.522e-05 | BU10: 4.477e-05 | BV10: 4.432e-05 | BW10: 4.388e-05 | BX10: 4.344e-05
A11: 8 | B11: 9.43e-05 | C11: 9.228e-05 | D11: 9.048e-05 | E11: 8.889e-05 | F11: 8.748e-05 | G11: 8.624e-05 | H11: 8.514e-05 | I11: 8.415e-05 | J11: 8.324e-05 | K11: 8.239e-05 | L11: 8.157e-05 | M11: 8.075e-05 | N11: 7.995e-05 | O11: 7.915e-05 | P11: 7.835e-05 | Q11: 7.757e-05 | R11: 7.68e-05 | S11: 7.603e-05 | T11: 7.527e-05 | U11: 7.451e-05 | V11: 7.377e-05 | W11: 7.303e-05 | X11: 7.23e-05 | Y11: 7.158e-05 | Z11: 7.086e-05 | AA11: 7.015e-05 | AB11: 6.945e-05 | AC11: 6.876e-05 | AD11: 6.807e-05 | AE11: 6.739e-05 | AF11: 6.672e-05 | AG11: 6.605e-05 | AH11: 6.539e-05 | AI11: 6.473e-05 | AJ11: 6.409e-05 | AK11: 6.345e-05 | AL11: 6.281e-05 | AM11: 6.218e-05 | AN11: 6.156e-05 | AO11: 6.095e-05 | AP11: 6.034e-05 | AQ11: 5.973e-05 | AR11: 5.914e-05 | AS11: 5.854e-05 | AT11: 5.796e-05 | AU11: 5.738e-05 | AV11: 5.681e-05 | AW11: 5.624e-05 | AX11: 5.567e-05 | AY11: 5.512e-05 | AZ11: 5.457e-05 | BA11: 5.402e-05 | BB11: 5.348e-05 | BC11: 5.295e-05 | BD11: 5.242e-05 | BE11: 5.189e-05 | BF11: 5.137e-05 | BG11: 5.086e-05 | BH11: 5.035e-05 | BI11: 4.985e-05 | BJ11: 4.935e-05 | BK11: 4.886e-05 | BL11: 4.837e-05 | BM11: 4.788e-05 | BN11: 4.74e-05 | BO11: 4.693e-05 | BP11: 4.646e-05 | BQ11: 4.6e-05 | BR11: 4.554e-05 | BS11: 4.508e-05 | BT11: 4.463e-05 | BU11: 4.418e-05 | BV11: 4.374e-05 | BW11: 4.331e-05 | BX11: 4.287e-05
A12: 9 | B12: 9.418e-05 | C12: 9.223e-05 | D12: 9.049e-05 | E12: 8.894e-05 | F12: 8.756e-05 | G12: 8.634e-05 | H12: 8.525e-05 | I12: 8.426e-05 | J12: 8.336e-05 | K12: 8.251e-05 | L12: 8.169e-05 | M12: 8.087e-05 | N12: 8.006e-05 | O12: 7.926e-05 | P12: 7.847e-05 | Q12: 7.768e-05 | R12: 7.691e-05 | S12: 7.614e-05 | T12: 7.538e-05 | U12: 7.462e-05 | V12: 7.388e-05 | W12: 7.314e-05 | X12: 7.241e-05 | Y12: 7.168e-05 | Z12: 7.096e-05 | AA12: 7.026e-05 | AB12: 6.955e-05 | AC12: 6.886e-05 | AD12: 6.817e-05 | AE12: 6.749e-05 | AF12: 6.681e-05 | AG12: 6.614e-05 | AH12: 6.548e-05 | AI12: 6.483e-05 | AJ12: 6.418e-05 | AK12: 6.354e-05 | AL12: 6.29e-05 | AM12: 6.227e-05 | AN12: 6.165e-05 | AO12: 6.103e-05 | AP12: 6.042e-05 | AQ12: 5.982e-05 | AR12: 5.922e-05 | AS12: 5.863e-05 | AT12: 5.804e-05 | AU12: 5.746e-05 | AV12: 5.689e-05 | AW12: 5.632e-05 | AX12: 5.576e-05 | AY12: 5.52e-05 | AZ12: 5.465e-05 | BA12: 5.41e-05 | BB12: 5.356e-05 | BC12: 5.302e-05 | BD12: 5.249e-05 | BE12: 5.197e-05 | BF12: 5.145e-05 | BG12: 5.093e-05 | BH12: 5.042e-05 | BI12: 4.992e-05 | BJ12: 4.942e-05 | BK12: 4.893e-05 | BL12: 4.844e-05 | BM12: 4.795e-05 | BN12: 4.747e-05 | BO12: 4.7e-05 | BP12: 4.653e-05 | BQ12: 4.606e-05 | BR12: 4.56e-05 | BS12: 4.515e-05 | BT12: 4.47e-05 | BU12: 4.425e-05 | BV12: 4.381e-05 | BW12: 4.337e-05 | BX12: 4.293e-05
A13: 10 | B13: 9.895e-05 | C13: 9.697e-05 | D13: 9.52e-05 | E13: 9.361e-05 | F13: 9.22e-05 | G13: 9.094e-05 | H13: 8.98e-05 | I13: 8.878e-05 | J13: 8.783e-05 | K13: 8.694e-05 | L13: 8.607e-05 | M13: 8.521e-05 | N13: 8.435e-05 | O13: 8.351e-05 | P13: 8.268e-05 | Q13: 8.185e-05 | R13: 8.103e-05 | S13: 8.022e-05 | T13: 7.942e-05 | U13: 7.862e-05 | V13: 7.784e-05 | W13: 7.706e-05 | X13: 7.629e-05 | Y13: 7.553e-05 | Z13: 7.477e-05 | AA13: 7.402e-05 | AB13: 7.328e-05 | AC13: 7.255e-05 | AD13: 7.182e-05 | AE13: 7.111e-05 | AF13: 7.039e-05 | AG13: 6.969e-05 | AH13: 6.899e-05 | AI13: 6.83e-05 | AJ13: 6.762e-05 | AK13: 6.694e-05 | AL13: 6.627e-05 | AM13: 6.561e-05 | AN13: 6.496e-05 | AO13: 6.431e-05 | AP13: 6.366e-05 | AQ13: 6.303e-05 | AR13: 6.24e-05 | AS13: 6.177e-05 | AT13: 6.115e-05 | AU13: 6.054e-05 | AV13: 5.994e-05 | AW13: 5.934e-05 | AX13: 5.875e-05 | AY13: 5.816e-05 | AZ13: 5.758e-05 | BA13: 5.7e-05 | BB13: 5.643e-05 | BC13: 5.587e-05 | BD13: 5.531e-05 | BE13: 5.475e-05 | BF13: 5.421e-05 | BG13: 5.366e-05 | BH13: 5.313e-05 | BI13: 5.26e-05 | BJ13: 5.207e-05 | BK13: 5.155e-05 | BL13: 5.103e-05 | BM13: 5.052e-05 | BN13: 5.002e-05 | BO13: 4.952e-05 | BP13: 4.902e-05 | BQ13: 4.853e-05 | BR13: 4.805e-05 | BS13: 4.757e-05 | BT13: 4.709e-05 | BU13: 4.662e-05 | BV13: 4.615e-05 | BW13: 4.569e-05 | BX13: 4.524e-05
A14: 11 | B14: 0.00011196 | C14: 0.0001098 | D14: 0.00010786 | E14: 0.00010612 | F14: 0.00010456 | G14: 0.00010316 | H14: 0.00010189 | I14: 0.00010074 | J14: 9.967e-05 | K14: 9.865e-05 | L14: 9.767e-05 | M14: 9.669e-05 | N14: 9.572e-05 | O14: 9.477e-05 | P14: 9.382e-05 | Q14: 9.288e-05 | R14: 9.195e-05 | S14: 9.103e-05 | T14: 9.012e-05 | U14: 8.922e-05 | V14: 8.833e-05 | W14: 8.745e-05 | X14: 8.657e-05 | Y14: 8.571e-05 | Z14: 8.485e-05 | AA14: 8.4e-05 | AB14: 8.316e-05 | AC14: 8.233e-05 | AD14: 8.15e-05 | AE14: 8.069e-05 | AF14: 7.988e-05 | AG14: 7.908e-05 | AH14: 7.829e-05 | AI14: 7.751e-05 | AJ14: 7.674e-05 | AK14: 7.597e-05 | AL14: 7.521e-05 | AM14: 7.446e-05 | AN14: 7.371e-05 | AO14: 7.297e-05 | AP14: 7.224e-05 | AQ14: 7.152e-05 | AR14: 7.081e-05 | AS14: 7.01e-05 | AT14: 6.94e-05 | AU14: 6.87e-05 | AV14: 6.802e-05 | AW14: 6.734e-05 | AX14: 6.666e-05 | AY14: 6.6e-05 | AZ14: 6.534e-05 | BA14: 6.468e-05 | BB14: 6.404e-05 | BC14: 6.34e-05 | BD14: 6.276e-05 | BE14: 6.213e-05 | BF14: 6.151e-05 | BG14: 6.09e-05 | BH14: 6.029e-05 | BI14: 5.969e-05 | BJ14: 5.909e-05 | BK14: 5.85e-05 | BL14: 5.791e-05 | BM14: 5.733e-05 | BN14: 5.676e-05 | BO14: 5.619e-05 | BP14: 5.563e-05 | BQ14: 5.508e-05 | BR14: 5.452e-05 | BS14: 5.398e-05 | BT14: 5.344e-05 | BU14: 5.29e-05 | BV14: 5.238e-05 | BW14: 5.185e-05 | BX14: 5.133e-05
... A113: 110 | B113: 1 | C113: 1 | D113: 1 | E113: 1 | F113: 1 | G113: 1 | H113: 1 | I113: 1 | J113: 1 | K113: 1 | L113: 1 | M113: 1 | N113: 1 | O113: 1 | P113: 1 | Q113: 1 | R113: 1 | S113: 1 | T113: 1 | U113: 1 | V113: 1 | W113: 1 | X113: 1 | Y113: 1 | Z113: 1 | AA113: 1 | AB113: 1 | AC113: 1 | AD113: 1 | AE113: 1 | AF113: 1 | AG113: 1 | AH113: 1 | AI113: 1 | AJ113: 1 | AK113: 1 | AL113: 1 | AM113: 1 | AN113: 1 | AO113: 1 | AP113: 1 | AQ113: 1 | AR113: 1 | AS113: 1 | AT113: 1 | AU113: 1 | AV113: 1 | AW113: 1 | AX113: 1 | AY113: 1 | AZ113: 1 | BA113: 1 | BB113: 1 | BC113: 1 | BD113: 1 | BE113: 1 | BF113: 1 | BG113: 1 | BH113: 1 | BI113: 1 | BJ113: 1 | BK113: 1 | BL113: 1 | BM113: 1 | BN113: 1 | BO113: 1 | BP113: 1 | BQ113: 1 | BR113: 1 | BS113: 1 | BT113: 1 | BU113: 1 | BV113: 1 | BW113: 1 | BX113: 1

Sheet Mortalidad_M
A1: qx proyectado = qx_2020 × Π(1 − AA x,t), tabla RV-M-2020. Filas: edad; columnas: año. Desde 2036 el factor AA se mantiene constante.
A2: Edad | B2: 2026 | C2: 2027 | D2: 2028 | E2: 2029 | F2: 2030 | G2: 2031 | H2: 2032 | I2: 2033 | J2: 2034 | K2: 2035 | L2: 2036 | M2: 2037 | N2: 2038 | O2: 2039 | P2: 2040 | Q2: 2041 | R2: 2042 | S2: 2043 | T2: 2044 | U2: 2045 | V2: 2046 | W2: 2047 | X2: 2048 | Y2: 2049 | Z2: 2050 | AA2: 2051 | AB2: 2052 | AC2: 2053 | AD2: 2054 | AE2: 2055 | AF2: 2056 | AG2: 2057 | AH2: 2058 | AI2: 2059 | AJ2: 2060 | AK2: 2061 | AL2: 2062 | AM2: 2063 | AN2: 2064 | AO2: 2065 | AP2: 2066 | AQ2: 2067 | AR2: 2068 | AS2: 2069 | AT2: 2070 | AU2: 2071 | AV2: 2072 | AW2: 2073 | AX2: 2074 | AY2: 2075 | AZ2: 2076 | BA2: 2077 | BB2: 2078 | BC2: 2079 | BD2: 2080 | BE2: 2081 | BF2: 2082 | BG2: 2083 | BH2: 2084 | BI2: 2085 | BJ2: 2086 | BK2: 2087 | BL2: 2088 | BM2: 2089 | BN2: 2090 | BO2: 2091 | BP2: 2092 | BQ2: 2093 | BR2: 2094 | BS2: 2095 | BT2: 2096 | BU2: 2097 | BV2: 2098 | BW2: 2099 | BX2: 2100
A3: 20 | B3: 0.00028308 | C3: 0.00028036 | D3: 0.00027765 | E3: 0.00027495 | F3: 0.00027226 | G3: 0.00026958 | H3: 0.00026691 | I3: 0.00026425 | J3: 0.00026162 | K3: 0.000259 | L3: 0.00025641 | M3: 0.00025385 | N3: 0.00025131 | O3: 0.0002488 | P3: 0.00024631 | Q3: 0.00024385 | R3: 0.00024141 | S3: 0.00023899 | T3: 0.0002366 | U3: 0.00023424 | V3: 0.0002319 | W3: 0.00022958 | X3: 0.00022728 | Y3: 0.00022501 | Z3: 0.00022276 | AA3: 0.00022053 | AB3: 0.00021833 | AC3: 0.00021614 | AD3: 0.00021398 | AE3: 0.00021184 | AF3: 0.00020972 | AG3: 0.00020763 | AH3: 0.00020555 | AI3: 0.00020349 | AJ3: 0.00020146 | AK3: 0.00019944 | AL3: 0.00019745 | AM3: 0.00019548 | AN3: 0.00019352 | AO3: 0.00019159 | AP3: 0.00018967 | AQ3: 0.00018777 | AR3: 0.0001859 | AS3: 0.00018404 | AT3: 0.0001822 | AU3: 0.00018037 | AV3: 0.00017857 | AW3: 0.00017678 | AX3: 0.00017502 | AY3: 0.00017327 | AZ3: 0.00017153 | BA3: 0.00016982 | BB3: 0.00016812 | BC3: 0.00016644 | BD3: 0.00016477 | BE3: 0.00016313 | BF3: 0.0001615 | BG3: 0.00015988 | BH3: 0.00015828 | BI3: 0.0001567 | BJ3: 0.00015513 | BK3: 0.00015358 | BL3: 0.00015205 | BM3: 0.00015052 | BN3: 0.00014902 | BO3: 0.00014753 | BP3: 0.00014605 | BQ3: 0.00014459 | BR3: 0.00014315 | BS3: 0.00014172 | BT3: 0.0001403 | BU3: 0.0001389 | BV3: 0.00013751 | BW3: 0.00013613 | BX3: 0.00013477
A4: 21 | B4: 0.00028928 | C4: 0.00028653 | D4: 0.00028379 | E4: 0.00028104 | F4: 0.0002783 | G4: 0.00027557 | H4: 0.00027285 | I4: 0.00027014 | J4: 0.00026745 | K4: 0.00026477 | L4: 0.00026213 | M4: 0.00025951 | N4: 0.00025691 | O4: 0.00025434 | P4: 0.0002518 | Q4: 0.00024928 | R4: 0.00024679 | S4: 0.00024432 | T4: 0.00024188 | U4: 0.00023946 | V4: 0.00023706 | W4: 0.00023469 | X4: 0.00023234 | Y4: 0.00023002 | Z4: 0.00022772 | AA4: 0.00022544 | AB4: 0.00022319 | AC4: 0.00022096 | AD4: 0.00021875 | AE4: 0.00021656 | AF4: 0.0002144 | AG4: 0.00021225 | AH4: 0.00021013 | AI4: 0.00020803 | AJ4: 0.00020595 | AK4: 0.00020389 | AL4: 0.00020185 | AM4: 0.00019983 | AN4: 0.00019783 | AO4: 0.00019585 | AP4: 0.0001939 | AQ4: 0.00019196 | AR4: 0.00019004 | AS4: 0.00018814 | AT4: 0.00018625 | AU4: 0.00018439 | AV4: 0.00018255 | AW4: 0.00018072 | AX4: 0.00017892 | AY4: 0.00017713 | AZ4: 0.00017536 | BA4: 0.0001736 | BB4: 0.00017187 | BC4: 0.00017015 | BD4: 0.00016845 | BE4: 0.00016676 | BF4: 0.00016509 | BG4: 0.00016344 | BH4: 0.00016181 | BI4: 0.00016019 | BJ4: 0.00015859 | BK4: 0.000157 | BL4: 0.00015543 | BM4: 0.00015388 | BN4: 0.00015234 | BO4: 0.00015082 | BP4: 0.00014931 | BQ4: 0.00014781 | BR4: 0.00014634 | BS4: 0.00014487 | BT4: 0.00014342 | BU4: 0.00014199 | BV4: 0.00014057 | BW4: 0.00013916 | BX4: 0.00013777
A5: 22 | B5: 0.0002985 | C5: 0.00029567 | D5: 0.00029283 | E5: 0.00029 | F5: 0.00028718 | G5: 0.00028436 | H5: 0.00028155 | I5: 0.00027875 | J5: 0.00027598 | K5: 0.00027322 | L5: 0.00027049 | M5: 0.00026778 | N5: 0.0002651 | O5: 0.00026245 | P5: 0.00025983 | Q5: 0.00025723 | R5: 0.00025466 | S5: 0.00025211 | T5: 0.00024959 | U5: 0.00024709 | V5: 0.00024462 | W5: 0.00024218 | X5: 0.00023975 | Y5: 0.00023736 | Z5: 0.00023498 | AA5: 0.00023263 | AB5: 0.00023031 | AC5: 0.000228 | AD5: 0.00022572 | AE5: 0.00022347 | AF5: 0.00022123 | AG5: 0.00021902 | AH5: 0.00021683 | AI5: 0.00021466 | AJ5: 0.00021252 | AK5: 0.00021039 | AL5: 0.00020829 | AM5: 0.0002062 | AN5: 0.00020414 | AO5: 0.0002021 | AP5: 0.00020008 | AQ5: 0.00019808 | AR5: 0.0001961 | AS5: 0.00019414 | AT5: 0.00019219 | AU5: 0.00019027 | AV5: 0.00018837 | AW5: 0.00018649 | AX5: 0.00018462 | AY5: 0.00018278 | AZ5: 0.00018095 | BA5: 0.00017914 | BB5: 0.00017735 | BC5: 0.00017557 | BD5: 0.00017382 | BE5: 0.00017208 | BF5: 0.00017036 | BG5: 0.00016866 | BH5: 0.00016697 | BI5: 0.0001653 | BJ5: 0.00016365 | BK5: 0.00016201 | BL5: 0.00016039 | BM5: 0.00015879 | BN5: 0.0001572 | BO5: 0.00015563 | BP5: 0.00015407 | BQ5: 0.00015253 | BR5: 0.000151 | BS5: 0.00014949 | BT5: 0.000148 | BU5: 0.00014652 | BV5: 0.00014505 | BW5: 0.0001436 | BX5: 0.00014217
A6: 23 | B6: 0.00030497 | C6: 0.00030206 | D6: 0.00029915 | E6: 0.00029624 | F6: 0.00029335 | G6: 0.00029046 | H6: 0.00028759 | I6: 0.00028473 | J6: 0.00028189 | K6: 0.00027908 | L6: 0.00027629 | M6: 0.00027352 | N6: 0.00027079 | O6: 0.00026808 | P6: 0.0002654 | Q6: 0.00026275 | R6: 0.00026012 | S6: 0.00025752 | T6: 0.00025494 | U6: 0.00025239 | V6: 0.00024987 | W6: 0.00024737 | X6: 0.0002449 | Y6: 0.00024245 | Z6: 0.00024002 | AA6: 0.00023762 | AB6: 0.00023525 | AC6: 0.00023289 | AD6: 0.00023057 | AE6: 0.00022826 | AF6: 0.00022598 | AG6: 0.00022372 | AH6: 0.00022148 | AI6: 0.00021927 | AJ6: 0.00021707 | AK6: 0.0002149 | AL6: 0.00021275 | AM6: 0.00021063 | AN6: 0.00020852 | AO6: 0.00020643 | AP6: 0.00020437 | AQ6: 0.00020233 | AR6: 0.0002003 | AS6: 0.0001983 | AT6: 0.00019632 | AU6: 0.00019435 | AV6: 0.00019241 | AW6: 0.00019049 | AX6: 0.00018858 | AY6: 0.0001867 | AZ6: 0.00018483 | BA6: 0.00018298 | BB6: 0.00018115 | BC6: 0.00017934 | BD6: 0.00017755 | BE6: 0.00017577 | BF6: 0.00017401 | BG6: 0.00017227 | BH6: 0.00017055 | BI6: 0.00016884 | BJ6: 0.00016716 | BK6: 0.00016548 | BL6: 0.00016383 | BM6: 0.00016219 | BN6: 0.00016057 | BO6: 0.00015896 | BP6: 0.00015737 | BQ6: 0.0001558 | BR6: 0.00015424 | BS6: 0.0001527 | BT6: 0.00015117 | BU6: 0.00014966 | BV6: 0.00014816 | BW6: 0.00014668 | BX6: 0.00014522
A7: 24 | B7: 0.00030654 | C7: 0.00030358 | D7: 0.00030063 | E7: 0.00029769 | F7: 0.00029477 | G7: 0.00029186 | H7: 0.00028896 | I7: 0.00028609 | J7: 0.00028323 | K7: 0.0002804 | L7: 0.0002776 | M7: 0.00027482 | N7: 0.00027207 | O7: 0.00026935 | P7: 0.00026666 | Q7: 0.00026399 | R7: 0.00026135 | S7: 0.00025874 | T7: 0.00025615 | U7: 0.00025359 | V7: 0.00025105 | W7: 0.00024854 | X7: 0.00024606 | Y7: 0.0002436 | Z7: 0.00024116 | AA7: 0.00023875 | AB7: 0.00023636 | AC7: 0.000234 | AD7: 0.00023166 | AE7: 0.00022934 | AF7: 0.00022705 | AG7: 0.00022478 | AH7: 0.00022253 | AI7: 0.00022031 | AJ7: 0.0002181 | AK7: 0.00021592 | AL7: 0.00021376 | AM7: 0.00021162 | AN7: 0.00020951 | AO7: 0.00020741 | AP7: 0.00020534 | AQ7: 0.00020329 | AR7: 0.00020125 | AS7: 0.00019924 | AT7: 0.00019725 | AU7: 0.00019528 | AV7: 0.00019332 | AW7: 0.00019139 | AX7: 0.00018948 | AY7: 0.00018758 | AZ7: 0.00018571 | BA7: 0.00018385 | BB7: 0.00018201 | BC7: 0.00018019 | BD7: 0.00017839 | BE7: 0.0001766 | BF7: 0.00017484 | BG7: 0.00017309 | BH7: 0.00017136 | BI7: 0.00016965 | BJ7: 0.00016795 | BK7: 0.00016627 | BL7: 0.00016461 | BM7: 0.00016296 | BN7: 0.00016133 | BO7: 0.00015972 | BP7: 0.00015812 | BQ7: 0.00015654 | BR7: 0.00015497 | BS7: 0.00015342 | BT7: 0.00015189 | BU7: 0.00015037 | BV7: 0.00014887 | BW7: 0.00014738 | BX7: 0.0001459
A8: 25 | B8: 0.00030115 | C8: 0.0002982 | D8: 0.00029528 | E8: 0.00029237 | F8: 0.00028948 | G8: 0.00028661 | H8: 0.00028376 | I8: 0.00028093 | J8: 0.00027812 | K8: 0.00027534 | L8: 0.00027259 | M8: 0.00026986 | N8: 0.00026717 | O8: 0.00026449 | P8: 0.00026185 | Q8: 0.00025923 | R8: 0.00025664 | S8: 0.00025407 | T8: 0.00025153 | U8: 0.00024902 | V8: 0.00024653 | W8: 0.00024406 | X8: 0.00024162 | Y8: 0.0002392 | Z8: 0.00023681 | AA8: 0.00023444 | AB8: 0.0002321 | AC8: 0.00022978 | AD8: 0.00022748 | AE8: 0.00022521 | AF8: 0.00022295 | AG8: 0.00022072 | AH8: 0.00021852 | AI8: 0.00021633 | AJ8: 0.00021417 | AK8: 0.00021203 | AL8: 0.00020991 | AM8: 0.00020781 | AN8: 0.00020573 | AO8: 0.00020367 | AP8: 0.00020164 | AQ8: 0.00019962 | AR8: 0.00019762 | AS8: 0.00019565 | AT8: 0.00019369 | AU8: 0.00019175 | AV8: 0.00018984 | AW8: 0.00018794 | AX8: 0.00018606 | AY8: 0.0001842 | AZ8: 0.00018236 | BA8: 0.00018053 | BB8: 0.00017873 | BC8: 0.00017694 | BD8: 0.00017517 | BE8: 0.00017342 | BF8: 0.00017168 | BG8: 0.00016997 | BH8: 0.00016827 | BI8: 0.00016658 | BJ8: 0.00016492 | BK8: 0.00016327 | BL8: 0.00016164 | BM8: 0.00016002 | BN8: 0.00015842 | BO8: 0.00015684 | BP8: 0.00015527 | BQ8: 0.00015372 | BR8: 0.00015218 | BS8: 0.00015066 | BT8: 0.00014915 | BU8: 0.00014766 | BV8: 0.00014618 | BW8: 0.00014472 | BX8: 0.00014327
A9: 26 | B9: 0.00029993 | C9: 0.00029696 | D9: 0.00029402 | E9: 0.0002911 | F9: 0.00028821 | G9: 0.00028534 | H9: 0.00028249 | I9: 0.00027967 | J9: 0.00027688 | K9: 0.00027411 | L9: 0.00027137 | M9: 0.00026865 | N9: 0.00026597 | O9: 0.00026331 | P9: 0.00026067 | Q9: 0.00025807 | R9: 0.00025549 | S9: 0.00025293 | T9: 0.0002504 | U9: 0.0002479 | V9: 0.00024542 | W9: 0.00024296 | X9: 0.00024053 | Y9: 0.00023813 | Z9: 0.00023575 | AA9: 0.00023339 | AB9: 0.00023106 | AC9: 0.00022875 | AD9: 0.00022646 | AE9: 0.00022419 | AF9: 0.00022195 | AG9: 0.00021973 | AH9: 0.00021754 | AI9: 0.00021536 | AJ9: 0.00021321 | AK9: 0.00021107 | AL9: 0.00020896 | AM9: 0.00020687 | AN9: 0.00020481 | AO9: 0.00020276 | AP9: 0.00020073 | AQ9: 0.00019872 | AR9: 0.00019674 | AS9: 0.00019477 | AT9: 0.00019282 | AU9: 0.00019089 | AV9: 0.00018898 | AW9: 0.00018709 | AX9: 0.00018522 | AY9: 0.00018337 | AZ9: 0.00018154 | BA9: 0.00017972 | BB9: 0.00017792 | BC9: 0.00017614 | BD9: 0.00017438 | BE9: 0.00017264 | BF9: 0.00017091 | BG9: 0.0001692 | BH9: 0.00016751 | BI9: 0.00016584 | BJ9: 0.00016418 | BK9: 0.00016254 | BL9: 0.00016091 | BM9: 0.0001593 | BN9: 0.00015771 | BO9: 0.00015613 | BP9: 0.00015457 | BQ9: 0.00015302 | BR9: 0.00015149 | BS9: 0.00014998 | BT9: 0.00014848 | BU9: 0.000147 | BV9: 0.00014553 | BW9: 0.00014407 | BX9: 0.00014263
A10: 27 | B10: 0.00030761 | C10: 0.00030453 | D10: 0.00030149 | E10: 0.00029848 | F10: 0.00029549 | G10: 0.00029254 | H10: 0.00028962 | I10: 0.00028672 | J10: 0.00028385 | K10: 0.00028101 | L10: 0.0002782 | M10: 0.00027542 | N10: 0.00027267 | O10: 0.00026994 | P10: 0.00026724 | Q10: 0.00026457 | R10: 0.00026192 | S10: 0.0002593 | T10: 0.00025671 | U10: 0.00025414 | V10: 0.0002516 | W10: 0.00024909 | X10: 0.0002466 | Y10: 0.00024413 | Z10: 0.00024169 | AA10: 0.00023927 | AB10: 0.00023688 | AC10: 0.00023451 | AD10: 0.00023217 | AE10: 0.00022984 | AF10: 0.00022755 | AG10: 0.00022527 | AH10: 0.00022302 | AI10: 0.00022079 | AJ10: 0.00021858 | AK10: 0.00021639 | AL10: 0.00021423 | AM10: 0.00021209 | AN10: 0.00020997 | AO10: 0.00020787 | AP10: 0.00020579 | AQ10: 0.00020373 | AR10: 0.00020169 | AS10: 0.00019968 | AT10: 0.00019768 | AU10: 0.0001957 | AV10: 0.00019375 | AW10: 0.00019181 | AX10: 0.00018989 | AY10: 0.00018799 | AZ10: 0.00018611 | BA10: 0.00018425 | BB10: 0.00018241 | BC10: 0.00018058 | BD10: 0.00017878 | BE10: 0.00017699 | BF10: 0.00017522 | BG10: 0.00017347 | BH10: 0.00017173 | BI10: 0.00017002 | BJ10: 0.00016832 | BK10: 0.00016663 | BL10: 0.00016497 | BM10: 0.00016332 | BN10: 0.00016168 | BO10: 0.00016007 | BP10: 0.00015847 | BQ10: 0.00015688 | BR10: 0.00015531 | BS10: 0.00015376 | BT10: 0.00015222 | BU10: 0.0001507 | BV10: 0.00014919 | BW10: 0.0001477 | BX10: 0.00014622
A11: 28 | B11: 0.00032527 | C11: 0.000322 | D11: 0.00031876 | E11: 0.00031556 | F11: 0.0003124 | G11: 0.00030927 | H11: 0.00030617 | I11: 0.00030311 | J11: 0.00030008 | K11: 0.00029707 | L11: 0.0002941 | M11: 0.00029116 | N11: 0.00028825 | O11: 0.00028537 | P11: 0.00028251 | Q11: 0.00027969 | R11: 0.00027689 | S11: 0.00027412 | T11: 0.00027138 | U11: 0.00026867 | V11: 0.00026598 | W11: 0.00026332 | X11: 0.00026069 | Y11: 0.00025808 | Z11: 0.0002555 | AA11: 0.00025295 | AB11: 0.00025042 | AC11: 0.00024791 | AD11: 0.00024543 | AE11: 0.00024298 | AF11: 0.00024055 | AG11: 0.00023814 | AH11: 0.00023576 | AI11: 0.0002334 | AJ11: 0.00023107 | AK11: 0.00022876 | AL11: 0.00022647 | AM11: 0.00022421 | AN11: 0.00022197 | AO11: 0.00021975 | AP11: 0.00021755 | AQ11: 0.00021537 | AR11: 0.00021322 | AS11: 0.00021109 | AT11: 0.00020898 | AU11: 0.00020689 | AV11: 0.00020482 | AW11: 0.00020277 | AX11: 0.00020074 | AY11: 0.00019873 | AZ11: 0.00019675 | BA11: 0.00019478 | BB11: 0.00019283 | BC11: 0.0001909 | BD11: 0.00018899 | BE11: 0.0001871 | BF11: 0.00018523 | BG11: 0.00018338 | BH11: 0.00018155 | BI11: 0.00017973 | BJ11: 0.00017793 | BK11: 0.00017616 | BL11: 0.00017439 | BM11: 0.00017265 | BN11: 0.00017092 | BO11: 0.00016921 | BP11: 0.00016752 | BQ11: 0.00016585 | BR11: 0.00016419 | BS11: 0.00016255 | BT11: 0.00016092 | BU11: 0.00015931 | BV11: 0.00015772 | BW11: 0.00015614 | BX11: 0.00015458
A12: 29 | B12: 0.0003419 | C12: 0.00033845 | D12: 0.00033504 | E12: 0.00033166 | F12: 0.00032833 | G12: 0.00032504 | H12: 0.00032178 | I12: 0.00031856 | J12: 0.00031537 | K12: 0.00031222 | L12: 0.00030909 | M12: 0.000306 | N12: 0.00030294 | O12: 0.00029991 | P12: 0.00029691 | Q12: 0.00029395 | R12: 0.00029101 | S12: 0.0002881 | T12: 0.00028521 | U12: 0.00028236 | V12: 0.00027954 | W12: 0.00027674 | X12: 0.00027398 | Y12: 0.00027124 | Z12: 0.00026852 | AA12: 0.00026584 | AB12: 0.00026318 | AC12: 0.00026055 | AD12: 0.00025794 | AE12: 0.00025536 | AF12: 0.00025281 | AG12: 0.00025028 | AH12: 0.00024778 | AI12: 0.0002453 | AJ12: 0.00024285 | AK12: 0.00024042 | AL12: 0.00023802 | AM12: 0.00023564 | AN12: 0.00023328 | AO12: 0.00023095 | AP12: 0.00022864 | AQ12: 0.00022635 | AR12: 0.00022409 | AS12: 0.00022185 | AT12: 0.00021963 | AU12: 0.00021743 | AV12: 0.00021526 | AW12: 0.0002131 | AX12: 0.00021097 | AY12: 0.00020886 | AZ12: 0.00020678 | BA12: 0.00020471 | BB12: 0.00020266 | BC12: 0.00020063 | BD12: 0.00019863 | BE12: 0.00019664 | BF12: 0.00019467 | BG12: 0.00019273 | BH12: 0.0001908 | BI12: 0.00018889 | BJ12: 0.000187 | BK12: 0.00018513 | BL12: 0.00018328 | BM12: 0.00018145 | BN12: 0.00017964 | BO12: 0.00017784 | BP12: 0.00017606 | BQ12: 0.0001743 | BR12: 0.00017256 | BS12: 0.00017083 | BT12: 0.00016912 | BU12: 0.00016743 | BV12: 0.00016576 | BW12: 0.0001641 | BX12: 0.00016246
A13: 30 | B13: 0.00035686 | C13: 0.00035325 | D13: 0.00034969 | E13: 0.00034616 | F13: 0.00034268 | G13: 0.00033924 | H13: 0.00033584 | I13: 0.00033248 | J13: 0.00032915 | K13: 0.00032586 | L13: 0.0003226 | M13: 0.00031938 | N13: 0.00031618 | O13: 0.00031302 | P13: 0.00030989 | Q13: 0.00030679 | R13: 0.00030372 | S13: 0.00030069 | T13: 0.00029768 | U13: 0.0002947 | V13: 0.00029176 | W13: 0.00028884 | X13: 0.00028595 | Y13: 0.00028309 | Z13: 0.00028026 | AA13: 0.00027746 | AB13: 0.00027468 | AC13: 0.00027194 | AD13: 0.00026922 | AE13: 0.00026652 | AF13: 0.00026386 | AG13: 0.00026122 | AH13: 0.00025861 | AI13: 0.00025602 | AJ13: 0.00025346 | AK13: 0.00025093 | AL13: 0.00024842 | AM13: 0.00024593 | AN13: 0.00024347 | AO13: 0.00024104 | AP13: 0.00023863 | AQ13: 0.00023624 | AR13: 0.00023388 | AS13: 0.00023154 | AT13: 0.00022923 | AU13: 0.00022693 | AV13: 0.00022466 | AW13: 0.00022242 | AX13: 0.00022019 | AY13: 0.00021799 | AZ13: 0.00021581 | BA13: 0.00021365 | BB13: 0.00021152 | BC13: 0.0002094 | BD13: 0.00020731 | BE13: 0.00020524 | BF13: 0.00020318 | BG13: 0.00020115 | BH13: 0.00019914 | BI13: 0.00019715 | BJ13: 0.00019518 | BK13: 0.00019322 | BL13: 0.00019129 | BM13: 0.00018938 | BN13: 0.00018749 | BO13: 0.00018561 | BP13: 0.00018375 | BQ13: 0.00018192 | BR13: 0.0001801 | BS13: 0.0001783 | BT13: 0.00017651 | BU13: 0.00017475 | BV13: 0.000173 | BW13: 0.00017127 | BX13: 0.00016956
A14: 31 | B14: 0.00037149 | C14: 0.00036774 | D14: 0.00036403 | E14: 0.00036037 | F14: 0.00035674 | G14: 0.00035316 | H14: 0.00034962 | I14: 0.00034612 | J14: 0.00034266 | K14: 0.00033923 | L14: 0.00033584 | M14: 0.00033248 | N14: 0.00032916 | O14: 0.00032587 | P14: 0.00032261 | Q14: 0.00031938 | R14: 0.00031619 | S14: 0.00031303 | T14: 0.00030989 | U14: 0.0003068 | V14: 0.00030373 | W14: 0.00030069 | X14: 0.00029768 | Y14: 0.00029471 | Z14: 0.00029176 | AA14: 0.00028884 | AB14: 0.00028595 | AC14: 0.00028309 | AD14: 0.00028026 | AE14: 0.00027746 | AF14: 0.00027469 | AG14: 0.00027194 | AH14: 0.00026922 | AI14: 0.00026653 | AJ14: 0.00026386 | AK14: 0.00026122 | AL14: 0.00025861 | AM14: 0.00025603 | AN14: 0.00025347 | AO14: 0.00025093 | AP14: 0.00024842 | AQ14: 0.00024594 | AR14: 0.00024348 | AS14: 0.00024104 | AT14: 0.00023863 | AU14: 0.00023625 | AV14: 0.00023388 | AW14: 0.00023154 | AX14: 0.00022923 | AY14: 0.00022694 | AZ14: 0.00022467 | BA14: 0.00022242 | BB14: 0.0002202 | BC14: 0.00021799 | BD14: 0.00021581 | BE14: 0.00021366 | BF14: 0.00021152 | BG14: 0.0002094 | BH14: 0.00020731 | BI14: 0.00020524 | BJ14: 0.00020319 | BK14: 0.00020115 | BL14: 0.00019914 | BM14: 0.00019715 | BN14: 0.00019518 | BO14: 0.00019323 | BP14: 0.0001913 | BQ14: 0.00018938 | BR14: 0.00018749 | BS14: 0.00018561 | BT14: 0.00018376 | BU14: 0.00018192 | BV14: 0.0001801 | BW14: 0.0001783 | BX14: 0.00017652
... A93: 110 | B93: 1 | C93: 1 | D93: 1 | E93: 1 | F93: 1 | G93: 1 | H93: 1 | I93: 1 | J93: 1 | K93: 1 | L93: 1 | M93: 1 | N93: 1 | O93: 1 | P93: 1 | Q93: 1 | R93: 1 | S93: 1 | T93: 1 | U93: 1 | V93: 1 | W93: 1 | X93: 1 | Y93: 1 | Z93: 1 | AA93: 1 | AB93: 1 | AC93: 1 | AD93: 1 | AE93: 1 | AF93: 1 | AG93: 1 | AH93: 1 | AI93: 1 | AJ93: 1 | AK93: 1 | AL93: 1 | AM93: 1 | AN93: 1 | AO93: 1 | AP93: 1 | AQ93: 1 | AR93: 1 | AS93: 1 | AT93: 1 | AU93: 1 | AV93: 1 | AW93: 1 | AX93: 1 | AY93: 1 | AZ93: 1 | BA93: 1 | BB93: 1 | BC93: 1 | BD93: 1 | BE93: 1 | BF93: 1 | BG93: 1 | BH93: 1 | BI93: 1 | BJ93: 1 | BK93: 1 | BL93: 1 | BM93: 1 | BN93: 1 | BO93: 1 | BP93: 1 | BQ93: 1 | BR93: 1 | BS93: 1 | BT93: 1 | BU93: 1 | BV93: 1 | BW93: 1 | BX93: 1

Sheet Calidad_datos
A1: Validaciones de la base de valores cuota (etapa 1)
A3: chequeo | B3: valor
A4: Duplicados fecha-fondo-AFP | B4: 0
A5: Días calendario faltantes dentro de cada serie | B5: 0
A6: Valores cuota nulos | B6: 0
A7: Retornos diarios sobre 10% (brutos) | B7: 2
A8: Registros provisorios | B8: 560
A10: Rebases por fusión detectados y neutralizados:
A11: 2004-03-01 fondo C PLANVITAL: +83.7% (Rebase por fusión, desaparece MAGISTER)
A12: 2004-03-01 fondo E PLANVITAL: +75.4% (Rebase por fusión, desaparece MAGISTER)

Sheet Rentabilidad
A1: Rentabilidad y riesgo por fondo, ago-2002 a ago-2026 (ponderado por afiliados)
A3: fondo | B3: rent_nominal_anual | C3: rent_real_anual | D3: inflacion_implicita | E3: max_caida_real | F3: prima_real_vs_E
A4: A | B4: 0.099430538 | C4: 0.058381319 | D4: 0.038784905 | E4: -0.4849059 | F4: 0.030160983
A5: B | B5: 0.090422322 | C5: 0.049709441 | D5: 0.038784905 | E5: -0.37109028 | F5: 0.021489105
A6: C | B6: 0.08284699 | C6: 0.042416771 | D6: 0.038785081 | E6: -0.24396643 | F6: 0.014196435
A7: D | B7: 0.073746334 | C7: 0.033656081 | D7: 0.038784906 | E7: -0.21910844 | F7: 0.0054357449
A8: E | B8: 0.068099947 | C8: 0.028220336 | D8: 0.038785083 | E8: -0.24334401 | F8: 0
A10: Real = valor cuota en UF. La inflación implícita es igual en los 5 fondos: control de consistencia.

Sheet Regimenes_HMM
A1: HMM gaussiano de 3 estados sobre retornos reales mensuales de los 5 fondos
A3: regimen | B3: nombre | C3: fondo | D3: retorno_anual | E3: vol_anual | F3: duracion_esperada_meses | G3: prob_estacionaria
A4: 0 | B4: Calma | C4: A | D4: 0.095536594 | E4: 0.092220026 | F4: 19.213097 | G4: 0.50036536
A5: 0 | B5: Calma | C5: B | D5: 0.078142762 | E5: 0.069091502 | F5: 19.213097 | G5: 0.50036536
A6: 0 | B6: Calma | C6: C | D6: 0.066802657 | E6: 0.048920817 | F6: 19.213097 | G6: 0.50036536
A7: 0 | B7: Calma | C7: D | D7: 0.055197979 | E7: 0.031465402 | F7: 19.213097 | G7: 0.50036536
A8: 0 | B8: Calma | C8: E | D8: 0.041531835 | E8: 0.024229533 | F8: 19.213097 | G8: 0.50036536
A9: 1 | B9: Tasas volátiles (post-2019) | C9: A | D9: 0.072567128 | E9: 0.1009909 | F9: 73.984942 | G9: 0.42625549
A10: 1 | B10: Tasas volátiles (post-2019) | C10: B | D10: 0.05810122 | E10: 0.081717472 | F10: 73.984942 | G10: 0.42625549
A11: 1 | B11: Tasas volátiles (post-2019) | C11: C | D11: 0.032016895 | E11: 0.070894559 | F11: 73.984942 | G11: 0.42625549
A12: 1 | B12: Tasas volátiles (post-2019) | C12: D | D12: 0.014431486 | E12: 0.080481954 | F12: 73.984942 | G12: 0.42625549
A13: 1 | B13: Tasas volátiles (post-2019) | C13: E | D13: 0.0037460951 | E13: 0.08914027 | F13: 73.984942 | G13: 0.42625549
A14: 2 | B14: Crisis bursátil | C14: A | D14: -0.12617163 | E14: 0.26260423 | F14: 2.5431592 | G14: 0.073379155
A15: 2 | B15: Crisis bursátil | C15: B | D15: -0.10421475 | E15: 0.18935619 | F15: 2.5431592 | G15: 0.073379155
... A18: 2 | B18: Crisis bursátil | C18: E | D18: 0.020813987 | E18: 0.076602487 | F18: 2.5431592 | G18: 0.073379155
A20: Selección por BIC: K=1: BIC -10,579.5; K=2: BIC -10,793.1; K=3: BIC -10,801.7
A21: Matriz de transición (fila = desde):
A22: 0.948 0.006 0.046
A23: 0.000 0.986 0.014
A24: 0.355 0.038 0.607

Sheet GARCH
A1: GARCH(1,1) sobre retornos reales diarios del sistema (QMLE)
A3: fondo | B3: alpha | C3: beta | D3: persistencia | E3: vida_media_dias | F3: vol_largo_plazo_anual | G3: vol_actual_anual
A4: A | B4: 0.088322706 | C4: 0.89166958 | D4: 0.97999229 | E4: 34.296258 | F4: 0.097830503 | G4: 0.072410639
A5: B | B5: 0.08631147 | C5: 0.89871758 | D5: 0.98502905 | E5: 45.952026 | F5: 0.074244411 | G5: 0.05719806
A6: C | B6: 0.092898146 | C6: 0.89198314 | D6: 0.98488128 | E6: 45.499507 | F6: 0.054082256 | G6: 0.039549769
A7: D | B7: 0.11180925 | C7: 0.88601672 | D7: 0.99782596 | E7: 318.48299 | F7: 0.077536985 | G7: 0.027625791
A8: E | B8: 0.096332578 | C8: 0.90233237 | D8: 0.99866495 | E8: 518.84379 | F8: 0.065326376 | G8: 0.033105141
A10: Persistencia ~1 en D y E: huella de un cambio de nivel de volatilidad (quiebre 2019), no de shocks transitorios.

Sheet MonteCarlo_H
A1: Pensión mensual simulada (UF) por estrategia · Hombre 25-65
A3: estrategia | B3: sexo | C3: p5 | D3: p25 | E3: mediana | F3: p75 | G3: p95 | H3: media | I3: cvar5 | J3: tasa_reemplazo_mediana | K3: prob_tr_meta
A4: Fondo A fijo | B4: H | C4: 7.2648754 | D4: 12.275817 | E4: 17.802965 | F4: 25.771666 | G4: 44.642541 | H4: 20.801559 | I4: 5.8626297 | J4: 0.49079629 | K4: 0.6396
A5: Fondo B fijo | B5: H | C5: 7.2241383 | D5: 10.657347 | E5: 14.045363 | F5: 18.417838 | G5: 27.706707 | H5: 15.26786 | I5: 6.1826246 | J5: 0.38720583 | K5: 0.4686
A6: Fondo C fijo | B6: H | C6: 6.3922361 | D6: 8.539258 | E6: 10.54242 | F6: 13.104481 | G6: 17.878564 | H6: 11.148294 | I6: 5.6767235 | J6: 0.2906359 | K6: 0.1638
A7: Fondo D fijo | B7: H | C7: 5.1220387 | D7: 6.9720579 | E7: 8.6849952 | F7: 10.641898 | G7: 13.949322 | H7: 8.9759979 | I7: 4.525742 | J7: 0.23942997 | K7: 0.0347
A8: Fondo E fijo | B8: H | C8: 4.3010839 | D8: 6.0149255 | E8: 7.5543054 | F8: 9.2217086 | G8: 11.678242 | H8: 7.7239595 | I8: 3.7865601 | J8: 0.20825885 | K8: 0.0051
A9: Por defecto (ley) | B9: H | C9: 6.023029 | D9: 8.1556444 | E9: 10.139957 | F9: 12.583057 | G9: 17.122766 | H9: 10.667932 | I9: 5.3132034 | J9: 0.27954071 | K9: 0.1313
A10: Ciclo de vida (aprox. FG) | B10: H | C10: 7.1963347 | D10: 10.856772 | E10: 14.759223 | F10: 20.187822 | G10: 32.511559 | H10: 16.689727 | I10: 6.1793388 | J10: 0.4068857 | K10: 0.5115
A11: Reactivo (market timing) | B11: H | C11: 5.5244933 | D11: 7.7000998 | E11: 9.6461415 | F11: 12.028011 | G11: 16.467899 | H11: 10.124276 | I11: 4.8640293 | J11: 0.26592708 | K11: 0.1029
A13: CNU al pensionarse: 193.9 · año de retiro 2066 · sueldo final 36.3 UF · traspasos (mediana, reactivo): 15
A14: cvar5 = pensión promedio en el 5% de peores escenarios.

Sheet MonteCarlo_M
A1: Pensión mensual simulada (UF) por estrategia · Mujer 25-60
A3: estrategia | B3: sexo | C3: p5 | D3: p25 | E3: mediana | F3: p75 | G3: p95 | H3: media | I3: cvar5 | J3: tasa_reemplazo_mediana | K3: prob_tr_meta
A4: Fondo A fijo | B4: M | C4: 4.5924594 | D4: 7.5183571 | E4: 10.545345 | F4: 14.843893 | G4: 24.495081 | H4: 12.032361 | I4: 3.8099613 | J4: 0.29071653 | K4: 0.2662
A5: Fondo B fijo | B5: M | C5: 4.6849037 | D5: 6.7111094 | E5: 8.5713103 | F5: 11.082352 | G5: 16.030197 | H5: 9.2444139 | I5: 4.0474503 | J5: 0.23629588 | K5: 0.084
A6: Fondo C fijo | B6: M | C6: 4.2460271 | D6: 5.5428936 | E6: 6.7252254 | F6: 8.2357239 | G6: 10.932315 | H6: 7.0590308 | I6: 3.7912552 | J6: 0.18540258 | K6: 0.0039
A7: Fondo D fijo | B7: M | C7: 3.4866518 | D7: 4.6785125 | E7: 5.700694 | F7: 6.887167 | G7: 8.7785528 | H7: 5.8594274 | I7: 3.0892704 | J7: 0.15715806 | K7: 0
A8: Fondo E fijo | B8: M | C8: 2.983086 | D8: 4.1300144 | E8: 5.0765531 | F8: 6.0916192 | G8: 7.5329028 | H8: 5.1537007 | I8: 2.6259582 | J8: 0.1399516 | K8: 0
A9: Por defecto (ley) | B9: M | C9: 3.9814199 | D9: 5.3415123 | E9: 6.4999967 | F9: 7.9383097 | G9: 10.490946 | H9: 6.7734899 | I9: 3.5444689 | J9: 0.17919342 | K9: 0.0019
A10: Ciclo de vida (aprox. FG) | B10: M | C10: 4.7744238 | D10: 7.2296387 | E10: 9.8391787 | F10: 13.424667 | G10: 21.401722 | H10: 11.050103 | I10: 4.0427089 | J10: 0.27124878 | K10: 0.201
A11: Reactivo (market timing) | B11: M | C11: 3.7035563 | D11: 5.0568733 | E11: 6.2413212 | F11: 7.6263375 | G11: 10.079276 | H11: 6.4748955 | I11: 3.2815906 | J11: 0.1720622 | K11: 0.0014
A13: CNU al pensionarse: 233.7 · año de retiro 2061 · sueldo final 36.3 UF · traspasos (mediana, reactivo): 14
A14: cvar5 = pensión promedio en el 5% de peores escenarios.

Sheet Sensibilidad
A1: Sensibilidad: rentabilidades históricas castigadas en 1 p.p. anual (hombre)
A3: estrategia | B3: sexo | C3: p5 | D3: p25 | E3: mediana | F3: p75 | G3: p95 | H3: media | I3: cvar5 | J3: tasa_reemplazo_mediana | K3: prob_tr_meta
A4: Fondo A fijo | B4: H | C4: 5.8369571 | D4: 9.6663651 | E4: 13.825609 | F4: 19.798052 | G4: 33.777626 | H4: 16.017775 | I4: 4.7572947 | J4: 0.3811476 | K4: 0.4665
A5: Fondo B fijo | B5: H | C5: 5.8346071 | D5: 8.4617454 | E5: 11.031612 | F5: 14.3436 | G5: 21.244007 | H5: 11.918288 | I5: 5.0191165 | J5: 0.30412206 | K5: 0.2389
A6: Fondo C fijo | B6: H | C6: 5.2105971 | D6: 6.8555885 | E6: 8.3921699 | F6: 10.349779 | G6: 13.906359 | H6: 8.8427029 | I6: 4.6469403 | J6: 0.2313573 | K6: 0.0379
A7: Fondo D fijo | B7: H | C7: 4.2224711 | D7: 5.6736249 | E7: 6.9861644 | F7: 8.492501 | G7: 11.006415 | H7: 7.2052227 | I7: 3.7571638 | J7: 0.19259621 | K7: 0.0016
A8: Fondo E fijo | B8: H | C8: 3.5891937 | D8: 4.9377498 | E8: 6.1411597 | F8: 7.4171015 | G8: 9.2753685 | H8: 6.2539468 | I8: 3.1801541 | J8: 0.16930092 | K8: 0.0003
A9: Por defecto (ley) | B9: H | C9: 4.9014074 | D9: 6.5489044 | E9: 8.0451238 | F9: 9.8994869 | G9: 13.278966 | H9: 8.434817 | I9: 4.3424337 | J9: 0.22178985 | K9: 0.0262
A10: Ciclo de vida (aprox. FG) | B10: H | C10: 5.836171 | D10: 8.5783748 | E10: 11.445023 | F10: 15.461914 | G10: 24.374419 | H10: 12.840764 | I10: 5.0490844 | J10: 0.31551906 | K10: 0.3012
A11: Reactivo (market timing) | B11: H | C11: 4.4931087 | D11: 6.1528957 | E11: 7.6642985 | F11: 9.4312231 | G11: 12.703654 | H11: 7.9862123 | I11: 3.9638879 | J11: 0.21129117 | K11: 0.0177

Sheet Backtest_2002_2026
A1: Evaluación retrospectiva con la historia real (sep-2002 a ago-2026)
A3: estrategia | B3: saldo_final_uf | C3: pension_mensual_uf | D3: n_traspasos | E3: vs_defecto | F3: sexo
A4: Fondo A fijo | B4: 1150.5409 | C4: 6.5014679 | D4: 0 | E4: 0.34062891 | F4: H
A5: Fondo B fijo | B5: 1069.2474 | C5: 6.0420951 | D5: 0 | E5: 0.24590438 | F5: H
A6: Fondo C fijo | B6: 945.42173 | C6: 5.3423818 | D6: 0 | E6: 0.10162068 | F6: H
A7: Fondo D fijo | B7: 843.78391 | C7: 4.7680476 | D7: 0 | E7: -0.016809346 | F7: H
A8: Fondo E fijo | B8: 784.33032 | C8: 4.4320877 | D8: 0 | E8: -0.086085632 | F8: H
A9: Por defecto (ley) | B9: 858.20986 | C9: 4.8495657 | D9: 0 | E9: 0 | F9: H
A10: Ciclo de vida (aprox. FG) | B10: 907.37572 | C10: 5.1273918 | D10: 0 | E10: 0.057288862 | F10: H
A11: Reactivo (market timing) | B11: 878.21702 | C11: 4.962622 | D11: 8 | E11: 0.023312673 | F11: H
A12: Fondo A fijo | B12: 1100.2198 | C12: 4.9220386 | D12: 0 | E12: 0.33899194 | F12: M
A13: Fondo B fijo | B13: 1023.0522 | C13: 4.576815 | D13: 0 | E13: 0.24507726 | F13: M
A14: Fondo C fijo | B14: 904.87463 | C14: 4.0481256 | D14: 0 | E14: 0.10125255 | F14: M
A15: Fondo D fijo | B15: 808.14213 | C15: 3.6153747 | D15: 0 | E15: -0.016473057 | F15: M
... A19: Reactivo (market timing) | B19: 840.18 | C19: 3.7587021 | D19: 8 | E19: 0.022517746 | F19: M
A21: Un solo camino histórico: útil como evidencia, no como probabilidad.

Sheet Bandas_FG
A1: Frecuencia histórica fuera de banda (AFP vs promedio de sus pares, 36 meses móviles)
A3: fondo | B3: banda | C3: pct_meses_sobre | D3: pct_meses_bajo | E3: pct_meses_fuera | F3: desv_p95_abs | G3: n_afp_meses
A4: A | B4: 0.01 | C4: 0.014563107 | D4: 0.025658807 | E4: 0.040221914 | F4: 0.0094752739 | G4: 1442
A5: A | B5: 0.015 | C5: 0 | D5: 0.013869626 | E5: 0.013869626 | F5: 0.0094752739 | G5: 1442
A6: A | B6: 0.02 | C6: 0 | D6: 0.013869626 | E6: 0.013869626 | F6: 0.0094752739 | G6: 1442
A7: A | B7: 0.024 | C7: 0 | D7: 0.011789182 | E7: 0.011789182 | F7: 0.0094752739 | G7: 1442
A8: A | B8: 0.029 | C8: 0 | D8: 0.0020804438 | E8: 0.0020804438 | F8: 0.0094752739 | G8: 1442
A9: A | B9: 0.04 | C9: 0 | D9: 0 | E9: 0 | F9: 0.0094752739 | G9: 1442
